Workbook

Sheet Metro_zhvi_uc_condo_tier_0.33_0
A1: RegionID | B1: SizeRank | C1: RegionName | D1: RegionType | E1: StateName | F1: 36556 | G1: 36585 | H1: 36616 | I1: 36646 | J1: 36677 | K1: 36707 | L1: 36738 | M1: 36769 | N1: 36799 | O1: 36830 | P1: 36860 | Q1: 36891 | R1: 36922 | S1: 36950 | T1: 36981 | U1: 37011 | V1: 37042 | W1: 37072 | X1: 37103 | Y1: 37134 | Z1: 37164 | AA1: 37195 | AB1: 37225 | AC1: 37256 | AD1: 37287 | AE1: 37315 | AF1: 37346 | AG1: 37376 | AH1: 37407 | AI1: 37437 | AJ1: 37468 | AK1: 37499 | AL1: 37529 | AM1: 37560 | AN1: 37590 | AO1: 37621 | AP1: 37652 | AQ1: 37680 | AR1: 37711 | AS1: 37741 | AT1: 37772 | AU1: 37802 | AV1: 37833 | AW1: 37864 | AX1: 37894 | AY1: 37925 | AZ1: 37955 | BA1: 37986 | BB1: 38017 | BC1: 38046 | BD1: 38077 | BE1: 38107 | BF1: 38138 | BG1: 38168 | BH1: 38199 | BI1: 38230 | BJ1: 38260 | BK1: 38291 | BL1: 38321 | BM1: 38352 | BN1: 38383 | BO1: 38411 | BP1: 38442 | BQ1: 38472 | BR1: 38503 | BS1: 38533 | BT1: 38564 | BU1: 38595 | BV1: 38625 | BW1: 38656 | BX1: 38686 | BY1: 38717 | BZ1: 38748 | CA1: 38776 | CB1: 38807 | CC1: 38837 | CD1: 38868 | CE1: 38898 | CF1: 38929 | CG1: 38960 | CH1: 38990 | CI1: 39021 | CJ1: 39051 | CK1: 39082 | CL1: 39113 | CM1: 39141 | CN1: 39172 | CO1: 39202 | CP1: 39233 | CQ1: 39263 | CR1: 39294 | CS1: 39325 | CT1: 39355 | CU1: 39386 | CV1: 39416 | CW1: 39447 | CX1: 39478 | CY1: 39507 | CZ1: 39538 | DA1: 39568 | DB1: 39599 | DC1: 39629 | DD1: 39660 | DE1: 39691 | DF1: 39721 | DG1: 39752 | DH1: 39782 | DI1: 39813 | DJ1: 39844 | DK1: 39872 | DL1: 39903 | DM1: 39933 | DN1: 39964 | DO1: 39994 | DP1: 40025 | DQ1: 40056 | DR1: 40086 | DS1: 40117 | DT1: 40147 | DU1: 40178 | DV1: 40209 | DW1: 40237 | DX1: 40268 | DY1: 40298 | DZ1: 40329 | EA1: 40359 | EB1: 40390 | EC1: 40421 | ED1: 40451 | EE1: 40482 | EF1: 40512 | EG1: 40543 | EH1: 40574 | EI1: 40602 | EJ1: 40633 | EK1: 40663 | EL1: 40694 | EM1: 40724 | EN1: 40755 | EO1: 40786 | EP1: 40816 | EQ1: 40847 | ER1: 40877 | ES1: 40908 | ET1: 40939 | EU1: 40968 | EV1: 40999 | EW1: 41029 | EX1: 41060 | EY1: 41090 | EZ1: 41121 | FA1: 41152 | FB1: 41182 | FC1: 41213 | FD1: 41243 | FE1: 41274 | FF1: 41305 | FG1: 41333 | FH1: 41364 | FI1: 41394 | FJ1: 41425 | FK1: 41455 | FL1: 41486 | FM1: 41517 | FN1: 41547 | FO1: 41578 | FP1: 41608 | FQ1: 41639 | FR1: 41670 | FS1: 41698 | FT1: 41729 | FU1: 41759 | FV1: 41790 | FW1: 41820 | FX1: 41851 | FY1: 41882 | FZ1: 41912 | GA1: 41943 | GB1: 41973 | GC1: 42004 | GD1: 42035 | GE1: 42063 | GF1: 42094 | GG1: 42124 | GH1: 42155 | GI1: 42185 | GJ1: 42216 | GK1: 42247 | GL1: 42277 | GM1: 42308 | GN1: 42338 | GO1: 42369 | GP1: 42400 | GQ1: 42429 | GR1: 42460 | GS1: 42490 | GT1: 42521 | GU1: 42551 | GV1: 42582 | GW1: 42613 | GX1: 42643 | GY1: 42674 | GZ1: 42704 | HA1: 42735 | HB1: 42766 | HC1: 42794 | HD1: 42825 | HE1: 42855 | HF1: 42886 | HG1: 42916 | HH1: 42947 | HI1: 42978 | HJ1: 43008 | HK1: 43039 | HL1: 43069 | HM1: 43100 | HN1: 43131 | HO1: 43159 | HP1: 43190 | HQ1: 43220 | HR1: 43251 | HS1: 43281 | HT1: 43312 | HU1: 43343 | HV1: 43373 | HW1: 43404 | HX1: 43434 | HY1: 43465 | HZ1: 43496 | IA1: 43524 | IB1: 43555 | IC1: 43585 | ID1: 43616 | IE1: 43646 | IF1: 43677 | IG1: 43708 | IH1: 43738 | II1: 43769 | IJ1: 43799 | IK1: 43830 | IL1: 43861 | IM1: 43890 | IN1: 43921 | IO1: 43951 | IP1: 43982 | IQ1: 44012 | IR1: 44043 | IS1: 44074 | IT1: 44104 | IU1: 44135 | IV1: 44165 | IW1: 44196 | IX1: 44227 | IY1: 44255 | IZ1: 44286 | JA1: 44316 | JB1: 44347 | JC1: 44377 | JD1: 44408 | JE1: 44439 | JF1: 44469 | JG1: 44500 | JH1: 44530 | JI1: 44561 | JJ1: 44592 | JK1: 44620 | JL1: 44651 | JM1: 44681 | JN1: 44712 | JO1: 44742 | JP1: 44773 | JQ1: 44804 | JR1: 44834 | JS1: 44865 | JT1: 44895 | JU1: 44926 | JV1: 44957 | JW1: 44985 | JX1: 45016 | JY1: 45046 | JZ1: 45077 | KA1: 45107 | KB1: 45138 | KC1: 45169 | KD1: 45199 | KE1: 45230 | KF1: 45260 | KG1: 45291 | KH1: 45322 | KI1: 45351 | KJ1: 45382 | KK1: 45412 | KL1: 45443 | KM1: 45473 | KN1: 45504 | KO1: 45535 | KP1: 45565 | KQ1: 45596 | KR1: 45626 | KS1: 45657 | KT1: 45688 | KU1: 45716 | KV1: 45747 | KW1: 45777 | KX1: 45808 | KY1: 45838 | KZ1: 45869 | LA1: 45900 | LB1: 45930
A2: 102001 | B2: 0 | C2: United States | D2: country | F2: 118113.17273417943 | G2: 118385.75016142862 | H2: 118728.15340175676 | I2: 119458.20157522308 | J2: 120302.91107163606 | K2: 121215.56404019454 | L2: 122193.09128874105 | M2: 123235.20624520548 | N2: 124305.1258551058 | O2: 125364.1640094117 | P2: 126398.35707127985 | Q2: 127437.18218274067 | R2: 128363.51035210508 | S2: 129248.00838353556 | T2: 130154.71073489216 | U2: 131195.93221600872 | V2: 132295.27375491356 | W2: 133387.66346345854 | X2: 134506.32708779228 | Y2: 135676.12481603114 | Z2: 136873.05181904358 | AA2: 138071.23830310666 | AB2: 139197.19381938127 | AC2: 140260.06994580335 | AD2: 141193.08 | AE2: 142092.48867010485 | AF2: 143020.38853807942 | AG2: 144066.33156046402 | AH2: 145216.76980984185 | AI2: 146438.39497133996 | AJ2: 147758.68993084205 | AK2: 149159.88757725203 | AL2: 150589.54696157607 | AM2: 151998.5324662272 | AN2: 153348.0250174684 | AO2: 154677.08142424378 | AP2: 155897.6002841977 | AQ2: 157090.73175966475 | AR2: 158314.49297956564 | AS2: 159643.56827650056 | AT2: 161067.62197919778 | AU2: 162474.3490354464 | AV2: 163923.44952157987 | AW2: 165400.9510926882 | AX2: 166944.03725984055 | AY2: 168473.1572401924 | AZ2: 169952.81734965986 | BA2: 171364.32360672022 | BB2: 172752.1965998139 | BC2: 174209.99273463292 | BD2: 175803.01619590665 | BE2: 177601.07865398555 | BF2: 179639.29609255702 | BG2: 181888.32509736542 | BH2: 184266.43247857722 | BI2: 186686.19002697698 | BJ2: 189095.45346279175 | BK2: 191420.69277501284 | BL2: 193569.14646221834 | BM2: 195702.6498827328 | BN2: 197756.6342797177 | BO2: 199916.46848743307 | BP2: 202211.81862787795 | BQ2: 204844.42292426576 | BR2: 207651.77166475382 | BS2: 210512.5076533509 | BT2: 213403.77249782594 | BU2: 216314.5246451569 | BV2: 219185.78352353876 | BW2: 221861.92817750399 | BX2: 224209.9175931944 | BY2: 226290.54322069747 | BZ2: 228093.75967627918 | CA2: 229764.04039457013 | CB2: 231460.28109171483 | CC2: 233293.49516202987 | CD2: 235067.67334549953 | CE2: 236543.40081213415 | CF2: 237534 | CG2: 238126.51513125468 | CH2: 238299.41852026814 | CI2: 238208.72153474123 | CJ2: 237986.74956817343 | CK2: 237677.31118227367 | CL2: 237316.17120263123 | CM2: 236959.6031703207 | CN2: 236541.51630825063 | CO2: 236060.42741759753 | CP2: 235340.6895662347 | CQ2: 234380.25652864474 | CR2: 233145.32389157396 | CS2: 231822.55197036066 | CT2: 230368.2654046747 | CU2: 228873.71832097028 | CV2: 227197.67372400968 | CW2: 225509.58902554866 | CX2: 223663.08149485066 | CY2: 221616.6212070773 | CZ2: 219325.25638784337 | DA2: 216817.3373111386 | DB2: 214267.9900009517 | DC2: 211670.1430859981 | DD2: 209018.4449100543 | DE2: 206174.52285504146 | DF2: 203315.49413297023 | DG2: 200501.8415041171 | DH2: 197787.31790940024 | DI2: 195113.32056780066 | DJ2: 192557.9968109458 | DK2: 190364.87228272518 | DL2: 188334.6103212977 | DM2: 186396.31590569942 | DN2: 184454.32156930453 | DO2: 182625.04149852364 | DP2: 180911.86307743794 | DQ2: 179294.9810373107 | DR2: 177804.48652051517 | DS2: 176602.91584594361 | DT2: 175849.8 | DU2: 175449.7255632454 | DV2: 175228.83 | DW2: 175005.05746885564 | DX2: 174785.19904115822 | DY2: 174677.34521213305 | DZ2: 174441.46853654168 | EA2: 173918.32 | EB2: 172916.37277722312 | EC2: 171677.43550693584 | ED2: 170295.2427772108 | EE2: 168915.78266204594 | EF2: 167543.61595968236 | EG2: 166357.5339305447 | EH2: 165293.68196720464 | EI2: 164373.11120889953 | EJ2: 163452.88635942675 | EK2: 162488.67625754108 | EL2: 161349.6750424579 | EM2: 160241.65200957144 | EN2: 159211.8232570787 | EO2: 158319.57132331826 | EP2: 157490.27180580003 | EQ2: 156739.81897433827 | ER2: 156171.12 | ES2: 155693.9686547326 | ET2: 155388.21623657155 | EU2: 155219.1926775181 | EV2: 155218.01457869727 | EW2: 155319.75583388205 | EX2: 155611.61937335166 | EY2: 156140.48218408925 | EZ2: 156839.5620359122 | FA2: 157474.7752008542 | FB2: 158166.68272010598 | FC2: 158899.04182178565 | FD2: 159824.59273065985 | FE2: 160867.77 | FF2: 162285.0061256717 | FG2: 163863.44 | FH2: 165490.55147749124 | FI2: 167110.39037267445 | FJ2: 168864.2665853903 | FK2: 170750.65272617392 | FL2: 172444.9648418534 | FM2: 174111.2129625987 | FN2: 175895.6393342237 | FO2: 177852.7649307154 | FP2: 179579.01202340765 | FQ2: 180989.96362841208 | FR2: 182220.70903142283 | FS2: 183546.21 | FT2: 184966.24722438375 | FU2: 186361.85834417967 | FV2: 187801.8600239368 | FW2: 188990.61354580728 | FX2: 190143.52808105774 | FY2: 191060.98916007453 | FZ2: 191953.17493614752 | GA2: 192667.52368465703 | GB2: 193541.85287714473 | GC2: 194555.42203825634 | GD2: 195594.1399297826 | GE2: 196471.87541641993 | GF2: 197304.22289691283 | GG2: 198140.77999708484 | GH2: 199106.6445961078 | GI2: 199973.7161387065 | GJ2: 200941.66194225414 | GK2: 202003.17158127166 | GL2: 203161.8768831851 | GM2: 204468.19858194466 | GN2: 205710.2565395151 | GO2: 206952.74805647475 | GP2: 208160.71047410544 | GQ2: 209291.2590379324 | GR2: 210299.95104191723 | GS2: 211331.14964293907 | GT2: 212323.79380704358 | GU2: 213440.9771947294 | GV2: 214169.2829656033 | GW2: 214761.55685899826 | GX2: 215349.7510021984 | GY2: 216238.03785923534 | GZ2: 217394.6824071506 | HA2: 218621.46470126766 | HB2: 219861.89326930477 | HC2: 221324.82693228012 | HD2: 222847.6776229708 | HE2: 224409.18036448877 | HF2: 225549.58063912555 | HG2: 226674.16925214967 | HH2: 227746.0200500161 | HI2: 228975.63742787697 | HJ2: 230132.9254550532 | HK2: 231477.3712177151 | HL2: 232797.8707120828 | HM2: 234283.22299115444 | HN2: 235693.85439539887 | HO2: 237129.05733579057 | HP2: 238753.14241618454 | HQ2: 240267.91774103107 | HR2: 241779.39225744584 | HS2: 242795.44951747262 | HT2: 244173.47984860363 | HU2: 245518.03374901848 | HV2: 247057.36846018277 | HW2: 248142.2425091382 | HX2: 249103.46074008537 | HY2: 249979.17570963225 | HZ2: 250801.99488395033 | IA2: 251529.83358524178 | IB2: 251989.16664284747 | IC2: 252300.33970196825 | ID2: 252455.2700295469 | IE2: 252642.6133983132 | IF2: 252858.92921158686 | IG2: 253209.4952261312 | IH2: 253541.97302461232 | II2: 254132.08 | IJ2: 255174.45613439838 | IK2: 256536.01746573168 | IL2: 258336.10687056326 | IM2: 259983.26942559364 | IN2: 261554.75695958108 | IO2: 262631.6564037264 | IP2: 263116.01827120176 | IQ2: 263124.94550191256 | IR2: 262959.7455268086 | IS2: 263330.32514127577 | IT2: 264625.4263851515 | IU2: 266686.9166064475 | IV2: 269405.03568339447 | IW2: 272287.16320565756 | IX2: 274840.71284340235 | IY2: 277200.33892445994 | IZ2: 279716.4249669022 | JA2: 282730.82203995757 | JB2: 286560.8416876408 | JC2: 290844.49555209716 | JD2: 295364.2856434649 | JE2: 299379.56611555786 | JF2: 302769.1953041227 | JG2: 306004.5273979492 | JH2: 309424.99 | JI2: 313117.3475667577 | JJ2: 316939.4615615633 | JK2: 321010.8406229487 | JL2: 325687.88846039464 | JM2: 330986.55226112524 | JN2: 336050.7243673953 | JO2: 340583.52298190043 | JP2: 343198.1057963383 | JQ2: 343900.49 | JR2: 343056.7257371903 | JS2: 342377.1267122102 | JT2: 342112.07333310513 | JU2: 341752.0307197794 | JV2: 340536.7095589911 | JW2: 338998.95079867286 | JX2: 337847.31082157604 | JY2: 337928.85060736415 | JZ2: 339042.86202301783 | KA2: 340877.7351223614 | KB2: 342815.1903065857 | KC2: 344923.90110005526 | KD2: 346803.5972722334 | KE2: 348154.4066168514 | KF2: 348870.55684771907 | KG2: 348810.82028840086 | KH2: 348983.41411332943 | KI2: 349337.4048453495 | KJ2: 350555.3302288458 | KK2: 351560.37 | KL2: 352072.95454610867 | KM2: 351564.1376233457 | KN2: 350908.33847663394 | KO2: 350617.55252563575 | KP2: 350650.9507329163 | KQ2: 350694.77488162456 | KR2: 350380.8703583943 | KS2: 350262.2658717094 | KT2: 350332.56236713525 | KU2: 350535.0523206988 | KV2: 350155.7395703274 | KW2: 349391.89442504785 | KX2: 348308.9548003795 | KY2: 347261.11175277777 | KZ2: 346184.6037260051 | LA2: 345474.4520092838 | LB2: 345216.0341246207
A3: 394913 | B3: 1 | C3: New York, NY | D3: msa | E3: NY | F3: 194003.67811348496 | G3: 194837.08749765053 | H3: 195663.97975353012 | I3: 197386.2004543111 | J3: 199256.45441391118 | K3: 201351.82146579563 | L3: 203626.5381770133 | M3: 205950.78003832922 | N3: 208372.5364502516 | O3: 210864.7161138246 | P3: 213402.59900007417 | Q3: 215892.26762041627 | R3: 218297.15555186162 | S3: 220797.9331764209 | T3: 223244.14964744818 | U3: 225723.41770133495 | V3: 228105.6622019622 | W3: 230566.50245872396 | X3: 232971.94138857318 | Y3: 235489.33258418785 | Z3: 238011.5933663774 | AA3: 240688.84573342153 | AB3: 243230.55586783463 | AC3: 245690.6343947261 | AD3: 248201.66189239456 | AE3: 250292.80479181543 | AF3: 252102.84029080765 | AG3: 253672.9181443029 | AH3: 255575.4268331343 | AI3: 257812.5375059629 | AJ3: 260219.61870833626 | AK3: 263186.35638127424 | AL3: 266382.8240901429 | AM3: 269686.6963425719 | AN3: 272577.9446205082 | AO3: 275304.6120803393 | AP3: 278005.54753288446 | AQ3: 280954.6560889101 | AR3: 284255.59062759805 | AS3: 287432.4511376076 | AT3: 290714.79858287744 | AU3: 294430.1755964654 | AV3: 298645.8050789213 | AW3: 302638.4186605622 | AX3: 305852.27973603504 | AY3: 308558.50510181556 | AZ3: 311047.2543402248 | BA3: 313524.7770350109 | BB3: 316127.63061027427 | BC3: 318893.95235879027 | BD3: 321742.50761547894 | BE3: 324624.2126951614 | BF3: 327955.3652763149 | BG3: 331607.7071017924 | BH3: 335801.2777557768 | BI3: 340173.2797082489 | BJ3: 345034.9969533654 | BK3: 349970.80439113587 | BL3: 354814.72415219847 | BM3: 359372.8424901112 | BN3: 363700.4942991866 | BO3: 367957.1600119806 | BP3: 372492.99628276547 | BQ3: 377476.6680831097 | BR3: 382668.5508098524 | BS3: 387735.0353000425 | BT3: 392681.3325281161 | BU3: 397631.0289566869 | BV3: 402537.5968879726 | BW3: 407771.6238548465 | BX3: 412809.02681791503 | BY3: 417810.99455215456 | BZ3: 422243.53041903005 | CA3: 426516.21298798436 | CB3: 429767.22603965463 | CC3: 432603.41753196117 | CD3: 435252.8269852742 | CE3: 437980.2051984074 | CF3: 439786.2853247332 | CG3: 440015.99253840203 | CH3: 438856.4488388877 | CI3: 436871.68264240894 | CJ3: 435172.87756536814 | CK3: 434285.28996345244 | CL3: 433508.39663824724 | CM3: 432935.0427570475 | CN3: 432885.1049933711 | CO3: 433361.81264394335 | CP3: 433770.7501856168 | CQ3: 432729.8282604393 | CR3: 431249.67539085896 | CS3: 429691.84924887255 | CT3: 428919.7815399898 | CU3: 428628.4869104225 | CV3: 428431.4863358825 | CW3: 428026.96158520615 | CX3: 427541.8316452881 | CY3: 427176.6102157671 | CZ3: 426331.58021717914 | DA3: 425252.66465257964 | DB3: 423363.9665540519 | DC3: 421430.3312607881 | DD3: 419100.3911502908 | DE3: 416777.5630231658 | DF3: 414592.7283100669 | DG3: 412459.91378961067 | DH3: 410175.42 | DI3: 406800.9738652906 | DJ3: 403056.10133063886 | DK3: 399433.71 | DL3: 397031.9327317847 | DM3: 393569.2190729157 | DN3: 390481.9858095125 | DO3: 386825.1024449097 | DP3: 383866.2279849316 | DQ3: 380440.2343250254 | DR3: 377488.4668698763 | DS3: 375325.5903761227 | DT3: 373944.39568475075 | DU3: 372637.87654754665 | DV3: 372195.7267458716 | DW3: 372513.4895390553 | DX3: 372609.64625587966 | DY3: 372733.87587469566 | DZ3: 372600.5252608514 | EA3: 373496.16785351373 | EB3: 374691.08602337213 | EC3: 375445.22 | ED3: 375770.8905699066 | EE3: 375453.2826735282 | EF3: 374376.3977754723 | EG3: 372907.88208226586 | EH3: 371741.08384750324 | EI3: 371242.2404073477 | EJ3: 372079.4658074828 | EK3: 372433.7115156741 | EL3: 372087.20872401446 | EM3: 370725.0750105896 | EN3: 369380.99 | EO3: 368974.8504833037 | EP3: 368874.2677431335 | EQ3: 368803.1478259552 | ER3: 368515.90916818724 | ES3: 368427.27 | ET3: 368165.4782090586 | EU3: 368023.8233136274 | EV3: 368151.62100178207 | EW3: 368640.8622945166 | EX3: 369613.25943767064 | EY3: 370406.9326393481 | EZ3: 371722.7907219977 | FA3: 372332.6180936927 | FB3: 372759.86097011965 | FC3: 372899.6023850506 | FD3: 373849.36434175685 | FE3: 374894.75122437876 | FF3: 376996.03865485784 | FG3: 379185.7757690649 | FH3: 381296.2292648037 | FI3: 382304.48222545465 | FJ3: 382853.0593323913 | FK3: 384228.91083804256 | FL3: 386031.6590752618 | FM3: 388274.34770206804 | FN3: 391224.59534180636 | FO3: 394934.6536213872 | FP3: 398459.3337375611 | FQ3: 400337.40840409044 | FR3: 401967.25220969575 | FS3: 404214.94736225554 | FT3: 407842.1774661707 | FU3: 411175.2308025321 | FV3: 414549.51517184783 | FW3: 416606.9965384875 | FX3: 418390.5240031443 | FY3: 419239.67163567705 | FZ3: 420507.00606106105 | GA3: 422335.34192703915 | GB3: 424867.89326743997 | GC3: 426971.37585903186 | GD3: 427614.8598859189 | GE3: 427148.81393083005 | GF3: 427202.40906692715 | GG3: 427773.11244165216 | GH3: 429290.0674689191 | GI3: 430082.0807785283 | GJ3: 431253.00357454916 | GK3: 433248.9449073763 | GL3: 436416.62768326356 | GM3: 440393.0327751259 | GN3: 443817.3734383462 | GO3: 447533.87748850643 | GP3: 449841.2997859752 | GQ3: 451322.7206406466 | GR3: 452119.0977526132 | GS3: 453709.43500766606 | GT3: 455754.02 | GU3: 457942.3981051785 | GV3: 459530.6170060779 | GW3: 460768.0197639407 | GX3: 461567.8281509623 | GY3: 462369.81715454045 | GZ3: 464018.53376751166 | HA3: 467125.4112744974 | HB3: 470333.04011206824 | HC3: 474763.2874362946 | HD3: 478645.50958673033 | HE3: 484172.28965491225 | HF3: 487791.8304675298 | HG3: 490939.8927294563 | HH3: 492548.26985446474 | HI3: 494940.3802471661 | HJ3: 496479.2278067931 | HK3: 499227.3382859551 | HL3: 500843.9578837909 | HM3: 504415.09928190423 | HN3: 508742.3151803854 | HO3: 513411.3590979975 | HP3: 517638.52664931555 | HQ3: 520983.9756871839 | HR3: 524739.1574790118 | HS3: 527266.99 | HT3: 529530.5581571735 | HU3: 531654.2093546331 | HV3: 535392.21 | HW3: 537323.8602033979 | HX3: 537617.46 | HY3: 535529.9179910092 | HZ3: 533213 | IA3: 531651.3503307719 | IB3: 529665.1070515532 | IC3: 528691.1852940907 | ID3: 528029.6677501966 | IE3: 528546.09 | IF3: 529164.9301780099 | IG3: 529113.0062911193 | IH3: 527527.02 | II3: 525067.9640381646 | IJ3: 525027.3555579475 | IK3: 526409.2371771128 | IL3: 529315.7177348536 | IM3: 529831.5485801022 | IN3: 529538.2969923363 | IO3: 528766.34 | IP3: 529217.42 | IQ3: 529459.6064270688 | IR3: 528135.54 | IS3: 525252.1700165503 | IT3: 524057.70135645056 | IU3: 524697.1301818523 | IV3: 526444.9098878488 | IW3: 528192.47 | IX3: 529109.7747131753 | IY3: 530598.8835745854 | IZ3: 532728.2676120572 | JA3: 534390.1169198077 | JB3: 536641.1378869187 | JC3: 537606.7237105193 | JD3: 539603.8937131208 | JE3: 540703.9171762319 | JF3: 541535.3493757002 | JG3: 543371.0085461889 | JH3: 546083.7706864756 | JI3: 548690.7934741345 | JJ3: 550403.9143906058 | JK3: 552547.5089621969 | JL3: 557176.2690874707 | JM3: 561843.2832817958 | JN3: 565456.8769129418 | JO3: 568153.17 | JP3: 568916.2162765759 | JQ3: 566661.2743062127 | JR3: 561007.5672345881 | JS3: 556233.0890056539 | JT3: 552461.3056695391 | JU3: 548421.2668492036 | JV3: 542883.8028532757 | JW3: 537019.8185847088 | JX3: 532519.3366089683 | JY3: 529665.2489655844 | JZ3: 528144.8503751393 | KA3: 527506.1865843037 | KB3: 527891.61 | KC3: 528615.7458924236 | KD3: 529281.2382226291 | KE3: 528946.2501462664 | KF3: 528061.9515343206 | KG3: 527318.7239919308 | KH3: 527802.0923167064 | KI3: 529506.6158955498 | KJ3: 533089.47 | KK3: 536880.9701267075 | KL3: 540298.89 | KM3: 542277.3652764736 | KN3: 544671.8938269974 | KO3: 547768.4419163711 | KP3: 550459.8359727431 | KQ3: 552335.3196780476 | KR3: 554364.3828309911 | KS3: 557095.49 | KT3: 559514.0083722525 | KU3: 561404.7409043759 | KV3: 562754.6748793576 | KW3: 563349.2063767047 | KX3: 563423.16 | KY3: 563428.6033601393 | KZ3: 564033.6093797943 | LA3: 564544.4821597596 | LB3: 565611.5850032168
A4: 753899 | B4: 2 | C4: Los Angeles, CA | D4: msa | E4: CA | F4: 173417.53 | G4: 174106.30342564918 | H4: 174986.69877608426 | I4: 176775.18836888426 | J4: 178728.01803509038 | K4: 180685.8520961071 | L4: 182695.5709187816 | M4: 184713.4370560704 | N4: 186657.31239986848 | O4: 188442.54853561553 | P4: 190110.88691492006 | Q4: 191811.53440077967 | R4: 193122.45796935272 | S4: 194539.81 | T4: 196110.79940447025 | U4: 198341.0012945132 | V4: 200682.5279878102 | W4: 202932.5716651895 | X4: 205146.23993258385 | Y4: 207311.79229085974 | Z4: 209470.91997347397 | AA4: 211541.16440029358 | AB4: 213413.82630359972 | AC4: 215261.90392792682 | AD4: 216783.09468559266 | AE4: 218516.27774702446 | AF4: 220583.77485064176 | AG4: 223315.31447885674 | AH4: 226432.47874339062 | AI4: 229721.72191167952 | AJ4: 233620.73362526228 | AK4: 237722.65594264105 | AL4: 241868.57014861747 | AM4: 245656.20558878838 | AN4: 249328.51536844857 | AO4: 252942.2640031942 | AP4: 256003.4 | AQ4: 258896.84409036147 | AR4: 261983.45004178863 | AS4: 265581.0063119474 | AT4: 269873.9191918648 | AU4: 273738.0125835906 | AV4: 278193.10223839036 | AW4: 282858.1773787669 | AX4: 288144.9123378495 | AY4: 292921.97 | AZ4: 297490.3 | BA4: 302028.9736385361 | BB4: 306942.6106424823 | BC4: 312520.26346639794 | BD4: 318904.54308069637 | BE4: 326418.4013664185 | BF4: 335335.7414721188 | BG4: 344558.02355739335 | BH4: 353105.6827615535 | BI4: 360264.8191995599 | BJ4: 366840.4863697781 | BK4: 373070.32583043445 | BL4: 377684.85753026744 | BM4: 381922.30961109046 | BN4: 385636.6180035031 | BO4: 390259.7750445196 | BP4: 395378.03292892175 | BQ4: 400705.4681911269 | BR4: 405774.7815350884 | BS4: 410452.55211748387 | BT4: 415766.9605227847 | BU4: 421657.17422155914 | BV4: 427835.1477615374 | BW4: 434109.5594619426 | BX4: 438841.65119389765 | BY4: 443258.6017164409 | BZ4: 446972.21314126765 | CA4: 450461.08172620443 | CB4: 453575.56082361116 | CC4: 456278.4679798924 | CD4: 459226.9727552159 | CE4: 461646.08462463925 | CF4: 462508.6624262053 | CG4: 463217.74641960516 | CH4: 462302.2640908365 | CI4: 461999.93520747795 | CJ4: 461139.1676622142 | CK4: 460729.0408995299 | CL4: 460629.68972967885 | CM4: 460377.2841476784 | CN4: 459685.7492641844 | CO4: 458234.24902613583 | CP4: 455737.6142316366 | CQ4: 453144.66710806295 | CR4: 449150.8254272363 | CS4: 444634.38463476434 | CT4: 439213.71293968166 | CU4: 433922.9338012216 | CV4: 429750.8234014047 | CW4: 425115.2457847506 | CX4: 420613.6656297894 | CY4: 414361.9947077197 | CZ4: 407239.49997876055 | DA4: 398156.1830013118 | DB4: 388401.8736490128 | DC4: 379424.5488076832 | DD4: 371602.7794492874 | DE4: 364878.25 | DF4: 359901.8051015543 | DG4: 355394.22 | DH4: 350584.24385000434 | DI4: 343921.4961704327 | DJ4: 338251.3841672195 | DK4: 334645.09880614496 | DL4: 332208.8241625171 | DM4: 329546.0242488149 | DN4: 326585.60490529845 | DO4: 323212.4871732324 | DP4: 320340.6078770761 | DQ4: 318518.01834423817 | DR4: 317726.41662723984 | DS4: 317415.29821915453 | DT4: 317995.43624375045 | DU4: 320264.3048149384 | DV4: 321727.6126962863 | DW4: 321686.4261112261 | DX4: 321439.7807188499 | DY4: 322341.90236970084 | DZ4: 324059.57500671246 | EA4: 323425.0098804427 | EB4: 321240.81374269276 | EC4: 317543.9937457052 | ED4: 313731.0867789848 | EE4: 309932.9810895033 | EF4: 306296.17 | EG4: 304126.4584811742 | EH4: 302809.62753362354 | EI4: 302470.50829124503 | EJ4: 301205.5028843463 | EK4: 299554.8875970519 | EL4: 295909.46693809045 | EM4: 293612.87678165414 | EN4: 291697.9028063281 | EO4: 289728.7218760038 | EP4: 286555.50028038694 | EQ4: 283156.59223677823 | ER4: 281497.56719450554 | ES4: 280571.83710909117 | ET4: 279677.02036789176 | EU4: 278134.22954410576 | EV4: 275862.05666793435 | EW4: 273719.89382497873 | EX4: 272372.3537378172 | EY4: 272470.2462008167 | EZ4: 273474.44801305985 | FA4: 275800.48678436683 | FB4: 279256.7241685925 | FC4: 283827.73251925054 | FD4: 289024.40683394944 | FE4: 294399.77606509224 | FF4: 299431.0364570318 | FG4: 303485.97927778866 | FH4: 306788.2713776925 | FI4: 310671.80350395315 | FJ4: 315955.48624325654 | FK4: 322608.6398764259 | FL4: 329263.50399747276 | FM4: 336127.7727851367 | FN4: 343267.80777795054 | FO4: 350607.7077209263 | FP4: 356946.39692511136 | FQ4: 361770.02251920017 | FR4: 364736.9770820785 | FS4: 366912.6029738867 | FT4: 368462.57447853143 | FU4: 370396.99956380646 | FV4: 372340.83540222497 | FW4: 374065.17351610615 | FX4: 375627.2 | FY4: 377169.87360221526 | FZ4: 379890.87829989893 | GA4: 383172.2526269772 | GB4: 386974.96730546205 | GC4: 390558.7484035059 | GD4: 392769.7801140123 | GE4: 393744.6757006039 | GF4: 393731.2494568241 | GG4: 393796.57779437426 | GH4: 394456.28647470864 | GI4: 395426.3254806716 | GJ4: 396285.8230201351 | GK4: 396218.66076732706 | GL4: 395492.18 | GM4: 394906.6465159126 | GN4: 394188.2147292406 | GO4: 393385.4552198748 | GP4: 395295.1015969965 | GQ4: 400289.58691925084 | GR4: 407414.5249890701 | GS4: 413437.2698588153 | GT4: 418004.47665506584 | GU4: 421685.5824117978 | GV4: 422563.7875154453 | GW4: 420513.03030927735 | GX4: 416506.01 | GY4: 413737.3300425757 | GZ4: 413495.82 | HA4: 415046.69624679716 | HB4: 420579.8795216624 | HC4: 428680.4042980112 | HD4: 438152.50724899786 | HE4: 445204.66 | HF4: 449979.78891239135 | HG4: 453738.41458353336 | HH4: 455117.59994301276 | HI4: 455729.30493518664 | HJ4: 456245.4368016284 | HK4: 459046.4382680163 | HL4: 462358.8929930918 | HM4: 465858.7208966019 | HN4: 470317.9682238612 | HO4: 476253.70804155787 | HP4: 482521.04588418367 | HQ4: 487696.2270179782 | HR4: 491646.3673621304 | HS4: 494349.2734028413 | HT4: 497606.0421900168 | HU4: 501788.99139267346 | HV4: 507304.1631622501 | HW4: 512449.29882372747 | HX4: 516083.15671333374 | HY4: 518226.73110685917 | HZ4: 516929.2023835641 | IA4: 512937.8742767383 | IB4: 507370.0327445348 | IC4: 503342.8471586791 | ID4: 500645.0865750084 | IE4: 498688.48055538937 | IF4: 498075.0086713214 | IG4: 499754.8824873529 | IH4: 503211.2317934137 | II4: 507049.5163313777 | IJ4: 510548.3661345861 | IK4: 514229.2780972741 | IL4: 516613.6548961235 | IM4: 517625.0710562188 | IN4: 517307.6038249997 | IO4: 517229.19957375986 | IP4: 516276.0940066795 | IQ4: 514837.08780572406 | IR4: 514174.7272770096 | IS4: 516679.67526207655 | IT4: 522091.9882567471 | IU4: 528900.3869860948 | IV4: 536767.5805298005 | IW4: 544328.7283598603 | IX4: 549681.0224433041 | IY4: 552159.2399845066 | IZ4: 553041.6565007064 | JA4: 555751.1004924608 | JB4: 561292.6817733619 | JC4: 569049.56 | JD4: 578193.1300865536 | JE4: 587293.1457176849 | JF4: 595981.3117145564 | JG4: 604564.4705182606 | JH4: 613202.3036471909 | JI4: 622869.1230167467 | JJ4: 631455.8489971535 | JK4: 639617.7003505132 | JL4: 647512.4167793331 | JM4: 655863.3611592092 | JN4: 663486.3116042884 | JO4: 668861.8231582022 | JP4: 671309.2792812745 | JQ4: 670232.5333431199 | JR4: 666942.13 | JS4: 664514.5509645584 | JT4: 663333.1377170017 | JU4: 662020.3258113157 | JV4: 656577.0423594166 | JW4: 648670.6395215594 | JX4: 641689.4249519372 | JY4: 639624.2291938872 | JZ4: 641477.8348109197 | KA4: 645885.2930386116 | KB4: 652161.3087235251 | KC4: 660368.8750551053 | KD4: 669267.4938323082 | KE4: 676728.4396833446 | KF4: 682096.4717376332 | KG4: 684593.3687139683 | KH4: 684721.0756490803 | KI4: 683147.3115697211 | KJ4: 682958.7821240468 | KK4: 683940.72 | KL4: 686204.1829107333 | KM4: 686848.3336531712 | KN4: 688477.22 | KO4: 690423.5280089597 | KP4: 693306.8742890371 | KQ4: 695121.5231437875 | KR4: 696724.3797149103 | KS4: 698138.9164345273 | KT4: 698341.3033356703 | KU4: 697768.8157228656 | KV4: 694990.4352833135 | KW4: 691879.4710980607 | KX4: 687274.6212791075 | KY4: 683191.3313864328 | KZ4: 679838.1351585736 | LA4: 677756.16 | LB4: 676659.3030073904
A5: 394463 | B5: 3 | C5: Chicago, IL | D5: msa | E5: IL | F5: 137679.23168239123 | G5: 137819.36948207777 | H5: 138122.8228128039 | I5: 138827.82758528533 | J5: 139724.14201686793 | K5: 140698.30222068017 | L5: 141682.0049895563 | M5: 142887.65281345195 | N5: 144292.76189579992 | O5: 145893.60474375638 | P5: 147258.7831879342 | Q5: 148404.68271799292 | R5: 149339.21934582296 | S5: 150171.53693789095 | T5: 151052.70524708592 | U5: 151956.55638414586 | V5: 153057.7625731558 | W5: 154249.7581396796 | X5: 155505.63430716528 | Y5: 156937.66219924626 | Z5: 158485.22112025754 | AA5: 160176.0936463347 | AB5: 161595.76806192505 | AC5: 162795.07531007528 | AD5: 163739.0020082997 | AE5: 164695.3471200081 | AF5: 165732.2592106981 | AG5: 166726.58569767003 | AH5: 167848.6093729801 | AI5: 168938.1692223821 | AJ5: 170102.38818498087 | AK5: 171433.06300320613 | AL5: 172877.70948791355 | AM5: 174405.08391606444 | AN5: 175501.65189110077 | AO5: 176473.15364584944 | AP5: 177297.76092167312 | AQ5: 178246.3261449053 | AR5: 179109.23192888757 | AS5: 180082.4311422558 | AT5: 180961.3504744559 | AU5: 181801.76550765513 | AV5: 182504.71153925764 | AW5: 183418.82389707747 | AX5: 184508.78545010102 | AY5: 185721.14349720793 | AZ5: 186822.36387715046 | BA5: 187708.8 | BB5: 188560.84090218807 | BC5: 189359.18807642566 | BD5: 190177.09054946853 | BE5: 191198.85813513887 | BF5: 192323.6366590046 | BG5: 193678.67773793964 | BH5: 194867.8550774826 | BI5: 196184.9848266535 | BJ5: 197449.56252659307 | BK5: 198836.16593476033 | BL5: 200108.24503733186 | BM5: 201381.6716521274 | BN5: 202450.39352219782 | BO5: 203564.65268714246 | BP5: 204697.49773553453 | BQ5: 205999.29 | BR5: 207321.29827109235 | BS5: 208639.31409445274 | BT5: 209847.16271427786 | BU5: 211127.53991091493 | BV5: 212576.27160266228 | BW5: 214189.31943129166 | BX5: 215457.42489255077 | BY5: 216544.45807156866 | BZ5: 217490.18714724024 | CA5: 218507.1811917897 | CB5: 219588.7139175765 | CC5: 220602.39844613476 | CD5: 221699.93648560412 | CE5: 222388.85430745734 | CF5: 222841.01381813688 | CG5: 223173.91690839233 | CH5: 223425.78922497653 | CI5: 223630.5192893799 | CJ5: 223722.65007506273 | CK5: 223937.58920488026 | CL5: 224322.7260770939 | CM5: 224816.4942832312 | CN5: 225210.02118668263 | CO5: 225342.67928776177 | CP5: 225196.50355220112 | CQ5: 224973.38728053225 | CR5: 224662.7610433359 | CS5: 224380.3966383637 | CT5: 223842.71229316425 | CU5: 223298.28481875823 | CV5: 222845.13991453892 | CW5: 222287.50875203652 | CX5: 221616.25565949592 | CY5: 219673.4760151972 | CZ5: 219032.82573299264 | DA5: 217410.08405235596 | DB5: 217331.1796803593 | DC5: 215643.76915874367 | DD5: 215094.8605911258 | DE5: 213280.7315726902 | DF5: 212028.6084037882 | DG5: 209803.53628402387 | DH5: 207754.1810872949 | DI5: 204982.37590730135 | DJ5: 201827.81991091397 | DK5: 199355.78995533288 | DL5: 196944.79327044493 | DM5: 195903.4720511235 | DN5: 194477.90970206496 | DO5: 193703.04894433115 | DP5: 192813.20691845473 | DQ5: 192151.88298559238 | DR5: 190654.57982033901 | DS5: 189025.97 | DT5: 187087.84101009765 | DU5: 186145.56523796593 | DV5: 185255.0694775954 | DW5: 185122.77534058839 | DX5: 184192.07424588114 | DY5: 184246.0714895171 | DZ5: 183419.30497805576 | EA5: 183327.6717701951 | EB5: 181164.93669604996 | EC5: 179327.64178499568 | ED5: 176761.7728757613 | EE5: 174755.1374523626 | EF5: 172124.1768531192 | EG5: 169516.6573921384 | EH5: 167113.59277691392 | EI5: 165110.59823883677 | EJ5: 163679.7889370091 | EK5: 162226.91155475483 | EL5: 161188.1865575389 | EM5: 159765.32330848044 | EN5: 158613.19919994764 | EO5: 157107.85700386172 | EP5: 155612.48001656643 | EQ5: 153489.8722611413 | ER5: 151723.34347204582 | ES5: 149645.72151326053 | ET5: 148106.2090002042 | EU5: 146437.89922727554 | EV5: 144985.5784902257 | EW5: 143554.7689451971 | EX5: 142471.80944984683 | EY5: 142028.69345098722 | EZ5: 141958.97840615062 | FA5: 141833.51318371124 | FB5: 141582.9212845617 | FC5: 141051.22446346402 | FD5: 140410.00569218394 | FE5: 139969.39541744205 | FF5: 140512.38831162636 | FG5: 141720.57177504097 | FH5: 143247.13245329328 | FI5: 145050.27683895908 | FJ5: 146652.84292446062 | FK5: 148690.18606991923 | FL5: 150156.0368358625 | FM5: 151914.22146999466 | FN5: 153674.6534763905 | FO5: 155945.21004579205 | FP5: 158023.7949777287 | FQ5: 159825.95715167208 | FR5: 161328.7660434025 | FS5: 163091.39688332917 | FT5: 165034.77565350183 | FU5: 166696.03490515988 | FV5: 167945.07852729067 | FW5: 168806.3757128752 | FX5: 169927.07925407254 | FY5: 171118.32004351346 | FZ5: 172260.12399803926 | GA5: 173260.56003915134 | GB5: 174151.3183352714 | GC5: 174935.44867412408 | GD5: 175518.37884764417 | GE5: 176020.5507068911 | GF5: 176834.4151719145 | GG5: 177462.61525710483 | GH5: 178303.94134620216 | GI5: 178820.9896650134 | GJ5: 179481.6413293997 | GK5: 179925.1645472337 | GL5: 180426.09291120296 | GM5: 181276.6298123603 | GN5: 182333.2482726639 | GO5: 183384.33073037988 | GP5: 184464.41668173517 | GQ5: 185546.22462519514 | GR5: 186404.72890885544 | GS5: 187352.75825610253 | GT5: 188342.0358813377 | GU5: 189430.4273562224 | GV5: 189823.0218087992 | GW5: 189838.03475610726 | GX5: 189909.5882392328 | GY5: 190418.77001032917 | GZ5: 191310.88874831432 | HA5: 192584.11285426156 | HB5: 193636.20772182939 | HC5: 194599.33638567408 | HD5: 195530.84194824533 | HE5: 196177.2286541455 | HF5: 196614.76241334467 | HG5: 196560.42453619733 | HH5: 196803.56831673055 | HI5: 197118.17442503935 | HJ5: 197802.62601215942 | HK5: 198620.54116148036 | HL5: 199620.7371630848 | HM5: 200634.76566037614 | HN5: 201665.40206442119 | HO5: 202607.27769722207 | HP5: 204051.94 | HQ5: 205377.64669284082 | HR5: 206373.87236097196 | HS5: 206259.50051352198 | HT5: 206273.20063456686 | HU5: 206333.50312177578 | HV5: 206669.32787945532 | HW5: 206630.1542747205 | HX5: 206570.56997049693 | HY5: 206776.68565462297 | HZ5: 207371.86251107717 | IA5: 208122.94196985595 | IB5: 208391.7958160589 | IC5: 208348.75002070834 | ID5: 208134.74440413286 | IE5: 207991.23816695708 | IF5: 207629.50688584952 | IG5: 207176.05 | IH5: 206499.8039565937 | II5: 206302.26882496887 | IJ5: 206447.5788830736 | IK5: 207237.9825336296 | IL5: 208190.36003974522 | IM5: 209216.38680100162 | IN5: 210034.45546505364 | IO5: 210468.28335795912 | IP5: 210110.30083600513 | IQ5: 209299.5197907509 | IR5: 208410.3855390353 | IS5: 208292.10962350585 | IT5: 209013.94826786415 | IU5: 210089.31070268468 | IV5: 211343.19491800133 | IW5: 212492.74163906943 | IX5: 213777.76371008833 | IY5: 215423.7160756878 | IZ5: 217180.07903119965 | JA5: 218619.40650910718 | JB5: 219903.06981951368 | JC5: 221402.34601183515 | JD5: 223265.3614155435 | JE5: 224595.20160288026 | JF5: 225114.9344047996 | JG5: 225311.78426110672 | JH5: 225839.11726002008 | JI5: 227124.33973048182 | JJ5: 228886.55569968963 | JK5: 231024.8734283927 | JL5: 233368.64830492952 | JM5: 235957.81087046396 | JN5: 237480.70420552176 | JO5: 238247.1419345104 | JP5: 237908.5655810266 | JQ5: 237345.7892354955 | JR5: 236654.0996350057 | JS5: 236221.45986318096 | JT5: 236192.26239356273 | JU5: 235916.7 | JV5: 235236.65211649108 | JW5: 234381.25838498445 | JX5: 234301.6753239842 | JY5: 235554.33095262863 | JZ5: 237717.08338900757 | KA5: 240135.08763177725 | KB5: 242482.9737256968 | KC5: 245209.20639339564 | KD5: 247800.80983197154 | KE5: 249744.22988814846 | KF5: 250898.4055805154 | KG5: 251280.61209623053 | KH5: 251185.3074810493 | KI5: 251691.44958996284 | KJ5: 252915.0926895208 | KK5: 254956.49083773248 | KL5: 256079.2054573159 | KM5: 256465.21739748112 | KN5: 256661.41945181857 | KO5: 257352.73904030418 | KP5: 257999.54842499617 | KQ5: 258537.78003571462 | KR5: 258738.82731337115 | KS5: 259318.9255128829 | KT5: 260397.79935037062 | KU5: 261562.73448179438 | KV5: 262424.70683549374 | KW5: 262176.37319588714 | KX5: 261746.67571184042 | KY5: 261420.54587217394 | KZ5: 261493.35823683706 | LA5: 261822.0518069399 | LB5: 262608.0321471847
A6: 394514 | B6: 4 | C6: Dallas, TX | D6: msa | E6: TX | F6: 86334.67203710743 | G6: 86369.26446992467 | H6: 86293.09921851214 | I6: 86232.53310201652 | J6: 86314.02531567986 | K6: 86390.85592399309 | L6: 86584.60434873994 | M6: 86751.44514172433 | N6: 86911.07349058468 | O6: 87004.431 | P6: 86955.433 | Q6: 87261.94292700574 | R6: 87570.213 | S6: 87402.27155500643 | T6: 87121.93079113196 | U6: 87052.27826075931 | V6: 87423.40157258972 | W6: 87405.76023584965 | X6: 87288.01228668737 | Y6: 87263.35199255297 | Z6: 87575.79600526538 | AA6: 87891.42794533119 | AB6: 88200.97010149964 | AC6: 88241.93338213321 | AD6: 88008.41745373876 | AE6: 87915.94770953529 | AF6: 87804.46251049063 | AG6: 87781.36257076236 | AH6: 87595.87350192723 | AI6: 87820.54090836283 | AJ6: 88015.011 | AK6: 88250.11 | AL6: 88439.07473792533 | AM6: 88805.68207775622 | AN6: 89189.47869053745 | AO6: 89370.77827544262 | AP6: 89450.10218900953 | AQ6: 89620.75901686866 | AR6: 90077.03295302509 | AS6: 90293.38585062574 | AT6: 90186.409 | AU6: 89946.00394384853 | AV6: 89714.464 | AW6: 89712.89973713054 | AX6: 89838.33505058989 | AY6: 90284.60416986035 | AZ6: 90940.66909167175 | BA6: 91214.30053494374 | BB6: 92066.17497814602 | BC6: 93083.89131686666 | BD6: 94844.57694555877 | BE6: 96146.86481028078 | BF6: 97021.204 | BG6: 97326.51858666229 | BH6: 97243.39542699807 | BI6: 97383.05284022978 | BJ6: 97528.28823641439 | BK6: 97610.77560056995 | BL6: 97418.25733724893 | BM6: 97185.26775540599 | BN6: 97575.03984846857 | BO6: 97683.02262278575 | BP6: 97949.92517251305 | BQ6: 97756.12497823061 | BR6: 98113.211 | BS6: 98295.532 | BT6: 98577.76006504548 | BU6: 98623.667 | BV6: 98867.52848822763 | BW6: 98785.97007329378 | BX6: 98742.83544663685 | BY6: 98503.02308071416 | BZ6: 98452.56603590875 | CA6: 98710.09677522676 | CB6: 98952.60609179632 | CC6: 99378.98216798755 | CD6: 99815.45443614719 | CE6: 100150.45832616113 | CF6: 100122.63721974682 | CG6: 99853.655 | CH6: 99991.19128155004 | CI6: 100503.69706887218 | CJ6: 100759.2684179261 | CK6: 100858.20597623526 | CL6: 100544.87736379798 | CM6: 100117.48929504344 | CN6: 99590.02678580744 | CO6: 99806.06150076546 | CP6: 100583.01390946587 | CQ6: 101224.89370744496 | CR6: 101740.54367523028 | CS6: 101994.3230121805 | CT6: 102411.23523720924 | CU6: 102414.13043044384 | CV6: 102698.67916431771 | CW6: 102899.28073054447 | CX6: 102812.09956020175 | CY6: 102071.4547528897 | CZ6: 101257.12078219751 | DA6: 100715.27415137699 | DB6: 100392.12686182243 | DC6: 100194.55452885879 | DD6: 100231.87570339616 | DE6: 100110.14604861192 | DF6: 99640.55378556618 | DG6: 98703.70139961071 | DH6: 97304.07064868859 | DI6: 96306.489 | DJ6: 95354.55812203554 | DK6: 95302.13609163884 | DL6: 95202.72762421689 | DM6: 95597.82478726724 | DN6: 95984.17172779492 | DO6: 96332.31 | DP6: 96476.56771290144 | DQ6: 96168.69504524059 | DR6: 95909.324 | DS6: 95629.72470581524 | DT6: 95773.73727106892 | DU6: 95927.17193929236 | DV6: 95820.57275888021 | DW6: 95528.162 | DX6: 94971.52549697911 | DY6: 94665.30750566714 | DZ6: 94246.50969501618 | EA6: 94009.55796857609 | EB6: 93502.374 | EC6: 92970.77333598089 | ED6: 92183.75056695343 | EE6: 91526.74749633142 | EF6: 90837.70056148405 | EG6: 90416.19336231839 | EH6: 89947.28192830848 | EI6: 89465.32724357965 | EJ6: 88771.784 | EK6: 88098.24640192784 | EL6: 87345.74701256512 | EM6: 86748.36578898363 | EN6: 86337.46358869565 | EO6: 86179.28491519934 | EP6: 86129.44470994233 | EQ6: 86041.32505178521 | ER6: 85911.90376935237 | ES6: 85676.18375644431 | ET6: 85330.48028021558 | EU6: 85295.34930901472 | EV6: 85427.05678488362 | EW6: 85755.18619319233 | EX6: 86105.96170736676 | EY6: 86782.14352698052 | EZ6: 87816.52092164899 | FA6: 88556.77874279713 | FB6: 89052.27289932128 | FC6: 89268.62850381667 | FD6: 89632.86214184544 | FE6: 90121.24881246826 | FF6: 90928.68739476125 | FG6: 92015.51236644282 | FH6: 92917.601 | FI6: 93547.38935193756 | FJ6: 94189.74573249249 | FK6: 95179.63040125823 | FL6: 96145.21243609725 | FM6: 96708.47415263846 | FN6: 96894.69772363798 | FO6: 97215.39965200501 | FP6: 97786.353 | FQ6: 98540.64662827073 | FR6: 99525.60512144626 | FS6: 100543.43495183025 | FT6: 101514.00808901332 | FU6: 102214.20822764833 | FV6: 102978.44735263323 | FW6: 103935.92511260622 | FX6: 105178.4527495666 | FY6: 106117.49165900885 | FZ6: 106765.04744646157 | GA6: 107074.86547475804 | GB6: 107711.73538416997 | GC6: 108530.48282191918 | GD6: 109493.65472210884 | GE6: 110532.48399001507 | GF6: 111571.4650133485 | GG6: 112492.96423682933 | GH6: 113389.6615068885 | GI6: 114425.52988935965 | GJ6: 115810.75553622755 | GK6: 117249.43125390164 | GL6: 118814.04603103151 | GM6: 120334.89044986381 | GN6: 121966.01952268406 | GO6: 123534.62450096507 | GP6: 125298.94604097698 | GQ6: 127041.30278705922 | GR6: 128667.17870174283 | GS6: 130298.84447692304 | GT6: 131833.7983078013 | GU6: 133515.98088532255 | GV6: 134779.67526921668 | GW6: 135856.97308270782 | GX6: 136981.76059760078 | GY6: 138316.47038736512 | GZ6: 140285.83462718627 | HA6: 142163.14801851613 | HB6: 144024.2825818834 | HC6: 145439.48165759433 | HD6: 146803.69250878345 | HE6: 148328.96815057987 | HF6: 149764.04573205914 | HG6: 151188.34457408587 | HH6: 152625.66165355718 | HI6: 154033.90914669007 | HJ6: 155507.04529164967 | HK6: 156897.28561774248 | HL6: 158395.00091398685 | HM6: 159901.2842554175 | HN6: 161340.48783563828 | HO6: 162751.18017010237 | HP6: 164391.4756913785 | HQ6: 165860.0549812153 | HR6: 167178.03104185534 | HS6: 167748.1416813106 | HT6: 168469.7071376807 | HU6: 169132.63981490376 | HV6: 170097.03761533226 | HW6: 170711.60905527085 | HX6: 171358.44 | HY6: 172113.56327442476 | HZ6: 172994.55156771038 | IA6: 173666.96217682443 | IB6: 173981.9488630362 | IC6: 173804.4241889032 | ID6: 173651.8066811063 | IE6: 173654.30606456613 | IF6: 173963.35531009454 | IG6: 174236.58212835467 | IH6: 174518.95849786283 | II6: 174889.84441404618 | IJ6: 175590.29021641833 | IK6: 176470.35484484257 | IL6: 177769.1997774799 | IM6: 179006.24274395275 | IN6: 179949.35347653864 | IO6: 180204.66594638862 | IP6: 179832.8605173484 | IQ6: 179216.6083744961 | IR6: 178954.94943649878 | IS6: 179288.38907211518 | IT6: 180213.19366334667 | IU6: 181282.04764384986 | IV6: 182730.53520150937 | IW6: 184247.40590916722 | IX6: 185752.4 | IY6: 187140.6092887695 | IZ6: 188723.29142458344 | JA6: 190663.3736465108 | JB6: 193042.52405393225 | JC6: 195620.35457844133 | JD6: 197896.16074939878 | JE6: 199717.19382308473 | JF6: 201184.30192595627 | JG6: 202763.41552362885 | JH6: 204652.44226623338 | JI6: 207030.70958008288 | JJ6: 210569.03916820104 | JK6: 214749.72267235597 | JL6: 219287.21119182793 | JM6: 224089.7295954269 | JN6: 229128.59983890897 | JO6: 233859.23921067882 | JP6: 236976.1809307574 | JQ6: 238275.46406327435 | JR6: 238477.34255282985 | JS6: 238785.33223151206 | JT6: 239117.33078652932 | JU6: 239130.00672904958 | JV6: 238473.00964150575 | JW6: 237467.55541394558 | JX6: 236789.68640639447 | JY6: 236380.5249625837 | JZ6: 236511.78726227744 | KA6: 237055.73097994915 | KB6: 237913.4009916728 | KC6: 239263.19976625402 | KD6: 240429.98574031857 | KE6: 241129.02192589702 | KF6: 241044.08699245515 | KG6: 240043.50054810135 | KH6: 239319.04952531797 | KI6: 239228.8745718595 | KJ6: 240112.84846351753 | KK6: 240831.82762541343 | KL6: 240576.20515262886 | KM6: 239467.5153695835 | KN6: 237720.74169921246 | KO6: 236107.9728359084 | KP6: 234790.49431432955 | KQ6: 233850.70133584845 | KR6: 232535.3680162338 | KS6: 231045.9564396327 | KT6: 229588.6507135829 | KU6: 228601.8473010297 | KV6: 227469.34732710672 | KW6: 226158.49346709764 | KX6: 224424.61349048678 | KY6: 222574.59827727397 | KZ6: 220802.01933517432 | LA6: 219743.92811618652 | LB6: 219085.3908770712
A7: 394692 | B7: 5 | C7: Houston, TX | D7: msa | E7: TX | F7: 79319.85222825693 | G7: 79447.07117488523 | H7: 79612.52696035626 | I7: 79625.35736980497 | J7: 79585.428 | K7: 79471.86273293519 | L7: 79864.43879324854 | M7: 79960.38291382282 | N7: 79998.56630776891 | O7: 79608.13887786216 | P7: 79859.53199789806 | Q7: 79952.63922154492 | R7: 80000.82481457328 | S7: 79820.48427375813 | T7: 79575.55036697947 | U7: 79508.077 | V7: 79289.37031411022 | W7: 79341.12218531819 | X7: 79303.78946461284 | Y7: 79195.313 | Z7: 79022.04678094204 | AA7: 79025.87438045883 | AB7: 78890.18805102292 | AC7: 78964.56956497011 | AD7: 78866.65675814675 | AE7: 78993.34253495112 | AF7: 78970.30379215466 | AG7: 79364.92510542586 | AH7: 79880.646 | AI7: 80369.705 | AJ7: 80847.13241611635 | AK7: 81193.68545239703 | AL7: 81369.65415503403 | AM7: 81143.31953690897 | AN7: 81178.28986472775 | AO7: 81269.00256017332 | AP7: 81656.81547588382 | AQ7: 81674.21491321694 | AR7: 81915.09509515342 | AS7: 81741.56748835224 | AT7: 81549.62345440358 | AU7: 81369.601 | AV7: 81098.29216339711 | AW7: 81301.756 | AX7: 81183.27943737732 | AY7: 81061.02692003771 | AZ7: 80599.52867328597 | BA7: 80640.53617748764 | BB7: 80929.27309092815 | BC7: 81340.78909989726 | BD7: 82298.974 | BE7: 83110.38097730842 | BF7: 84193.19320013358 | BG7: 84298.96720236102 | BH7: 84546.58437096946 | BI7: 84496.93399661944 | BJ7: 84670.96154600826 | BK7: 85014.63278772523 | BL7: 85048.43 | BM7: 85168.22525946899 | BN7: 85334.73673791031 | BO7: 85730.53127104774 | BP7: 86021.17822521446 | BQ7: 86231.18884672523 | BR7: 86438.05855153235 | BS7: 86344.69804372963 | BT7: 86276.50964736364 | BU7: 86235.53476872729 | BV7: 86491.20347285084 | BW7: 86472.477 | BX7: 86565.21374628192 | BY7: 86844.90285027558 | BZ7: 87361.01325407805 | CA7: 87493.82988291544 | CB7: 87331.67127062523 | CC7: 87233.83837005358 | CD7: 87663.14824923097 | CE7: 87944.72874871298 | CF7: 88219.56304163249 | CG7: 88051.04457565812 | CH7: 88413.12250708177 | CI7: 88557.77661185166 | CJ7: 89060.89617902231 | CK7: 89078.60535934666 | CL7: 89254.861 | CM7: 88864.24952586967 | CN7: 88687.09370647056 | CO7: 88834.38410496461 | CP7: 89192.674 | CQ7: 89287.838 | CR7: 89015.39003294906 | CS7: 88793.387 | CT7: 89003.58840345881 | CU7: 89142.24172422824 | CV7: 89358.08081028222 | CW7: 89166.09101820028 | CX7: 88720.92718881155 | CY7: 88182.51101117679 | CZ7: 87687.75152438333 | DA7: 87399.61201731313 | DB7: 87150.53399946241 | DC7: 87059.70689058422 | DD7: 86906.986 | DE7: 86670.463 | DF7: 86307.454 | DG7: 86013.86168526493 | DH7: 85465.51062386316 | DI7: 84863.40976104827 | DJ7: 84167.63614042754 | DK7: 83940.45183235622 | DL7: 83734.93290487785 | DM7: 83713.04409678627 | DN7: 83679.92666871274 | DO7: 83828.01457943453 | DP7: 83955.85577361095 | DQ7: 83911.54997803416 | DR7: 83772.07584576626 | DS7: 83562.333 | DT7: 83510.37283746955 | DU7: 83495.97022813807 | DV7: 83333.03738482333 | DW7: 83170.04189939609 | DX7: 82953.19257449482 | DY7: 82854.95466082527 | DZ7: 82705.60603699357 | EA7: 82443.60878995429 | EB7: 81922.005 | EC7: 81143.44730887686 | ED7: 80422.35484429811 | EE7: 79889.797 | EF7: 79436.58789916629 | EG7: 78987.96461278961 | EH7: 78431.732 | EI7: 77975.69847219806 | EJ7: 77394.40152510256 | EK7: 77065.01661701991 | EL7: 76854.81265433914 | EM7: 76905.33571691082 | EN7: 76986.54774441007 | EO7: 77172.39701486808 | EP7: 77299.27446141162 | EQ7: 77382.357 | ER7: 77100.31023092671 | ES7: 76853.72369763453 | ET7: 76634.127 | EU7: 76724.89570393169 | EV7: 76839.03611230885 | EW7: 76989.54751565016 | EX7: 77092.63616087666 | EY7: 77358.97270912895 | EZ7: 77763.89019185388 | FA7: 78112.868 | FB7: 78249.03 | FC7: 78288.62580174518 | FD7: 78320.81256584097 | FE7: 78392.10101027554 | FF7: 78591.60838341605 | FG7: 79030.68554231284 | FH7: 79583.55892941331 | FI7: 80097.61575909087 | FJ7: 80745.66023487726 | FK7: 81672.39535674962 | FL7: 82559.30815735948 | FM7: 83405.06896194995 | FN7: 83914.25490635667 | FO7: 84606.49471646304 | FP7: 85195.57989300751 | FQ7: 86049.53829632608 | FR7: 86939.995 | FS7: 87890.814 | FT7: 88789.74213598603 | FU7: 89725.94402954662 | FV7: 90793.97096260918 | FW7: 91978.04200771365 | FX7: 93382.24589567252 | FY7: 94824.60909745307 | FZ7: 95954.516 | GA7: 96872.91940557228 | GB7: 97807.81338536895 | GC7: 99030.18403603655 | GD7: 100236.2631161856 | GE7: 101436.4701590265 | GF7: 102595.3009297602 | GG7: 103681.6973634759 | GH7: 104626.40360036753 | GI7: 105431.5915631031 | GJ7: 106158.5946105836 | GK7: 106931.55685091286 | GL7: 107596.40282098159 | GM7: 108248.93385910668 | GN7: 108789.95094934564 | GO7: 109446.23021460207 | GP7: 110144.63891875748 | GQ7: 110772.24634647199 | GR7: 111139.61564323814 | GS7: 111518.21811306679 | GT7: 111821.2730141071 | GU7: 112252.62211544473 | GV7: 112402.72449789617 | GW7: 112598.26569941454 | GX7: 112905.95308577456 | GY7: 113383.05956998299 | GZ7: 113974.86373159844 | HA7: 114481.08470141859 | HB7: 114983.98259234855 | HC7: 115381.4213139668 | HD7: 115758.36364037788 | HE7: 116154.56751691907 | HF7: 116348.11724381329 | HG7: 116526.42576121911 | HH7: 116660.87846269377 | HI7: 116860.68336452328 | HJ7: 117065.12526110234 | HK7: 117401.59067659303 | HL7: 117836.83124824135 | HM7: 118248.8048661942 | HN7: 118498.86979317664 | HO7: 118787.14165793873 | HP7: 119281.77745119273 | HQ7: 119693.41998983204 | HR7: 119996.67356420551 | HS7: 120119.30738279637 | HT7: 120490.5149886236 | HU7: 120869.99 | HV7: 121254.12924296287 | HW7: 121571.76744767222 | HX7: 121935.38990225764 | HY7: 122521.43974119499 | HZ7: 123141.31056029255 | IA7: 123743.20706928913 | IB7: 124017.17258395332 | IC7: 123948.47943915775 | ID7: 123819.35914984027 | IE7: 123696.02254030162 | IF7: 123585.99588160998 | IG7: 123389.09969841196 | IH7: 123232.15977477613 | II7: 123301.7898858112 | IJ7: 123677.29833906311 | IK7: 124178.96575219529 | IL7: 124806.81374925662 | IM7: 125376.75042506635 | IN7: 125967.21230788808 | IO7: 126367.91108449169 | IP7: 126444.32009478121 | IQ7: 126191.02083166999 | IR7: 125813.11264695227 | IS7: 125823.71455565479 | IT7: 126295.31370572651 | IU7: 127129.76297265205 | IV7: 128188.73767771297 | IW7: 129187.78071647295 | IX7: 130078.3077122072 | IY7: 130836.2941872105 | IZ7: 131806.6351549226 | JA7: 133050.13557860954 | JB7: 134623.6853301714 | JC7: 136418.78738915687 | JD7: 138054.36851053324 | JE7: 139422.86435950038 | JF7: 140529.7885831646 | JG7: 141751.52798767065 | JH7: 143070.45043021571 | JI7: 144575.23660324168 | JJ7: 146491.08720689255 | JK7: 148528.2433583781 | JL7: 150653.94780567524 | JM7: 152708.32748776363 | JN7: 154775.28043286654 | JO7: 156874.83381791995 | JP7: 158494.49585820697 | JQ7: 159578.1925968822 | JR7: 160238.40093638888 | JS7: 160932.49324782702 | JT7: 161776.42710809654 | JU7: 162416.64003004844 | JV7: 162836.60248587411 | JW7: 163015.3818327913 | JX7: 163304.4164636902 | JY7: 163652.04379680654 | JZ7: 164177.29632026484 | KA7: 164716.62306636103 | KB7: 165149.70121975694 | KC7: 165559.38132195573 | KD7: 165667.61368522668 | KE7: 165513.32200879103 | KF7: 165217.53530397496 | KG7: 164618.33540674942 | KH7: 164156.68278245858 | KI7: 163643.1091285358 | KJ7: 163581.25602831013 | KK7: 163616.9799177861 | KL7: 163434.74717831673 | KM7: 162845.2044674578 | KN7: 161914.5980091701 | KO7: 160950.0763364512 | KP7: 159995.5927132376 | KQ7: 159104.76047044154 | KR7: 158214.20012763303 | KS7: 157392.04183600858 | KT7: 156580.3899409843 | KU7: 155738.91721994287 | KV7: 154742.39860019577 | KW7: 153843.01703077284 | KX7: 152956.7625002521 | KY7: 152125.1477779036 | KZ7: 151177.5710368716 | LA7: 150395.34260177618 | LB7: 149608.88939365247
A8: 395209 | B8: 6 | C8: Washington, DC | D8: msa | E8: VA | F8: 122659.26228364315 | G8: 122682.23924869635 | H8: 122876.99605602103 | I8: 123302.57592994999 | J8: 123952.70099593503 | K8: 124656.00851764617 | L8: 125547.70082632887 | M8: 126655.12125054588 | N8: 127870.1211841083 | O8: 129058.79324086937 | P8: 130149.66036934056 | Q8: 131398.65035082737 | R8: 132531.98921745134 | S8: 133570.67893104776 | T8: 134569.5844624081 | U8: 135864.45226393096 | V8: 137462.9897398588 | W8: 139166.91084772858 | X8: 140958.86470753327 | Y8: 142750.92186811054 | Z8: 144562.4307012432 | AA8: 146281.04830604166 | AB8: 148017.97615805187 | AC8: 149732.60459265418 | AD8: 151261.21481520563 | AE8: 152638.51908887477 | AF8: 154019.51150264204 | AG8: 155723.13957993407 | AH8: 157734.14411423562 | AI8: 160020.49339437767 | AJ8: 162554.44816598084 | AK8: 165206.48999009797 | AL8: 167811.03590930687 | AM8: 170244.42630567032 | AN8: 172568.06444409615 | AO8: 174784.8614054932 | AP8: 176660.96508371932 | AQ8: 178662.87639786807 | AR8: 180703.5561806207 | AS8: 183124.22099681883 | AT8: 185574.94516011552 | AU8: 188230.6168905463 | AV8: 190924.1681569851 | AW8: 193598.10689066214 | AX8: 196333.34472305325 | AY8: 199105.64006862743 | AZ8: 201766.46116301688 | BA8: 204303.54101963027 | BB8: 206601.3695864665 | BC8: 209088.11030320008 | BD8: 211792.82126016764 | BE8: 215156.7838132803 | BF8: 219076.3485256848 | BG8: 223539.15218807754 | BH8: 228637.10136722683 | BI8: 233858.8019260443 | BJ8: 239319.19693291662 | BK8: 244092.8549192392 | BL8: 248440.54 | BM8: 252392.06393623192 | BN8: 256439.30129345445 | BO8: 260453.01498925398 | BP8: 264782.6374735877 | BQ8: 269939.3196446407 | BR8: 275859.9965490838 | BS8: 281819.8772689699 | BT8: 287395.0597054682 | BU8: 292339.9863273511 | BV8: 296912.58211440523 | BW8: 300914.9822022419 | BX8: 304231.91149254463 | BY8: 307083.3796768804 | BZ8: 309434.9228434003 | CA8: 311724.8287667225 | CB8: 314135.03853914584 | CC8: 316177.13613706705 | CD8: 317454.1906234958 | CE8: 317751.8333966711 | CF8: 317457.6304809498 | CG8: 316677.21038992103 | CH8: 314958.60328463966 | CI8: 312734.31594076584 | CJ8: 310756.8286564798 | CK8: 309475.72799504554 | CL8: 308594.59736960655 | CM8: 307997.7163397718 | CN8: 307369.2396746629 | CO8: 307185.4236826832 | CP8: 306842.4322918354 | CQ8: 305872.4837920054 | CR8: 304315.6729791146 | CS8: 302435.2851837315 | CT8: 300823.13580440526 | CU8: 298920.68815253465 | CV8: 296871.4419427022 | CW8: 294559.7605684975 | CX8: 292543.41419621796 | CY8: 290249.85060762055 | CZ8: 287645.79846563307 | DA8: 284612.28176812513 | DB8: 281229.4210094709 | DC8: 277404.12480906845 | DD8: 273456.6316346251 | DE8: 269671.4595543676 | DF8: 266216.6405965185 | DG8: 262962.48 | DH8: 260099.68708481974 | DI8: 257552.8530424669 | DJ8: 254665.8225458099 | DK8: 251787.88356320202 | DL8: 248964.3096945157 | DM8: 246842.4142453767 | DN8: 245363.32902741767 | DO8: 244367.66736282743 | DP8: 243032.7760432399 | DQ8: 241447.61413476805 | DR8: 239731.84630760908 | DS8: 238571.33671914448 | DT8: 237936.86853882743 | DU8: 237867.11872436618 | DV8: 238526.6201451622 | DW8: 239123.13612461183 | DX8: 239907.29502295275 | DY8: 240609.5363533738 | DZ8: 241374.72823299188 | EA8: 241570.8064793007 | EB8: 240977.26208923318 | EC8: 239928.02224716148 | ED8: 238609.79077794147 | EE8: 237265.2104737391 | EF8: 235965.64086330912 | EG8: 235293.82807704379 | EH8: 235172.05606459896 | EI8: 235741.87432487457 | EJ8: 235826.47949321065 | EK8: 235463.61807631794 | EL8: 234378.56855943214 | EM8: 233352.73638134703 | EN8: 232103.39752092733 | EO8: 230798.98638353497 | EP8: 229511.41656404888 | EQ8: 228576.59814217707 | ER8: 228233.54351911496 | ES8: 227844.89659992457 | ET8: 227587.40852456095 | EU8: 227451.01402365114 | EV8: 227960.50345146586 | EW8: 228826.52710527423 | EX8: 229567.0072416989 | EY8: 230578.08685331067 | EZ8: 231533.0105388459 | FA8: 232733.16026439017 | FB8: 233963.35210398145 | FC8: 235417.41208039838 | FD8: 236830.92222079812 | FE8: 237982.35519270893 | FF8: 239390.90616078195 | FG8: 241327.45 | FH8: 243334.85836109213 | FI8: 245091.08608791523 | FJ8: 246658.59294708364 | FK8: 248336.46917085003 | FL8: 249772.58919860973 | FM8: 251062.4039603828 | FN8: 252371.07545587336 | FO8: 253976.29 | FP8: 255515.96049892265 | FQ8: 256798.9761474002 | FR8: 257684.24368252754 | FS8: 258626.31 | FT8: 259720.65 | FU8: 260910.7431723342 | FV8: 261773.86492841432 | FW8: 262158.69495919836 | FX8: 262209.8194907565 | FY8: 262041.33 | FZ8: 262014.31803745838 | GA8: 262002.63418836333 | GB8: 262110.78103479455 | GC8: 262221.84931087954 | GD8: 262331.65851793316 | GE8: 262378.19 | GF8: 262492.47249758797 | GG8: 262429.7896843912 | GH8: 262241.4709229464 | GI8: 261869.5417173888 | GJ8: 261717.22858425358 | GK8: 261854.29382733573 | GL8: 261955.40858131726 | GM8: 262358.79915712756 | GN8: 262794.3608640069 | GO8: 263360.4546729268 | GP8: 263857.59673298936 | GQ8: 264106.66238567483 | GR8: 264173.9817158784 | GS8: 264022.1078239659 | GT8: 263825.2140466668 | GU8: 263788.54566861497 | GV8: 263443.74676952214 | GW8: 263161.00954433595 | GX8: 263193.8965023328 | GY8: 263871.07942971983 | GZ8: 264968.05134985404 | HA8: 265973.9538182772 | HB8: 266815.94944802456 | HC8: 267644.3121627329 | HD8: 268262.1634467957 | HE8: 268915.3680907684 | HF8: 269102.02114557393 | HG8: 269387.6396307571 | HH8: 269689.6369192644 | HI8: 270252.04722487275 | HJ8: 270931.7061477644 | HK8: 271929.35 | HL8: 272919.2244730561 | HM8: 274063.52636785613 | HN8: 274866.54 | HO8: 275617.44367529213 | HP8: 276304.0138185853 | HQ8: 276843.5057951196 | HR8: 277452.0323823824 | HS8: 277599.0103168613 | HT8: 278452.3627547827 | HU8: 279230.39893578115 | HV8: 280398.18973515386 | HW8: 281218.7599676856 | HX8: 282187.9615840308 | HY8: 283300.32279585395 | HZ8: 284404.31340541336 | IA8: 285608.96449453896 | IB8: 286829.3139509861 | IC8: 288080.60376005206 | ID8: 289072.16119346267 | IE8: 289799.9126525002 | IF8: 290427.0009424644 | IG8: 291209.8666915146 | IH8: 292057.37001552695 | II8: 293100.8751754485 | IJ8: 294508.3528139935 | IK8: 296426.3711734143 | IL8: 298884.1433070561 | IM8: 301389.16673904244 | IN8: 303906.96601641964 | IO8: 305839.1569130932 | IP8: 306740.5508983632 | IQ8: 306735.43816853425 | IR8: 306564.54 | IS8: 307195.8443882063 | IT8: 308750.6430072792 | IU8: 310866.75839948707 | IV8: 313379.8814494772 | IW8: 315750.2190632611 | IX8: 317568.7653530497 | IY8: 318871.7310367421 | IZ8: 320315.8283859093 | JA8: 322168.8098756437 | JB8: 324491.55652490054 | JC8: 326543.2272645868 | JD8: 327908.9653582473 | JE8: 328706.9022572274 | JF8: 328863.09 | JG8: 329175.2179012893 | JH8: 329682.6116420187 | JI8: 330774.3939465024 | JJ8: 331998.0652021233 | JK8: 333350.6172772737 | JL8: 335328.48023421346 | JM8: 337872.0767406924 | JN8: 340337.39362881175 | JO8: 342122.0220765295 | JP8: 342596.4123825796 | JQ8: 342052.45971024735 | JR8: 340835.50181016815 | JS8: 340340.0238628507 | JT8: 340356.45807194454 | JU8: 340475.6261925753 | JV8: 339871.1212221398 | JW8: 339370.6341461174 | JX8: 339116.6011087027 | JY8: 340215.0683442622 | JZ8: 342208.25508202164 | KA8: 345103.3635179198 | KB8: 347915.15 | KC8: 350387.7306830597 | KD8: 352493.1173930334 | KE8: 353713.7547609921 | KF8: 354386.87163478887 | KG8: 353970.6234242064 | KH8: 353839.5944832091 | KI8: 354152.83457801834 | KJ8: 355645.77003514953 | KK8: 357265.8187532352 | KL8: 358389.11422734056 | KM8: 358510.69514168036 | KN8: 358419.1717501722 | KO8: 358426.2274036209 | KP8: 358916.7215295324 | KQ8: 359701.92417270987 | KR8: 360407.8579359033 | KS8: 361574.0974927484 | KT8: 362715.92705694045 | KU8: 363751.28061904124 | KV8: 363731.47302346263 | KW8: 363168.2146503101 | KX8: 362146.7906397113 | KY8: 361199.7564518998 | KZ8: 360174.3126938135 | LA8: 359490.4122809155 | LB8: 359124.25496100937
